<?xml version="1.0" ?>
<!-- =================================================================================== -->
<!-- |    This document was autogenerated by xacro from rr1.urdf.xacro                 | -->
<!-- |    EDITING THIS FILE BY HAND IS NOT RECOMMENDED                                 | -->
<!-- =================================================================================== -->
<robot name="robot_name">
    <!-- Specify some standard inertial calculations
    https://en.wikipedia.org/wiki/List_of_moments_of_inertia -->
    <!-- Gazebo's ros2_control plugin -->
    <gazebo>
        <plugin filename="libgazebo_ros2_control.so" name="gazebo_ros2_control">
            <robot_sim_type>gazebo_ros2_control/GazeboSystem</robot_sim_type>
            <parameters>/home/envilon/dev_ws/install/rr1_description/share/rr1_description/config/rr1_controller.yaml</parameters>
        </plugin>
        <plugin name="gazebo_ros_control">
            <robotNamespace>/</robotNamespace>
        </plugin>
    </gazebo>
    <ros2_control name="GazeboSystem" type="system">
        <hardware>
            <plugin>gazebo_ros2_control/GazeboSystem</plugin>
        </hardware>
        <joint name="shoulder_joint">
            <command_interface name="position">
                <param name="min">-3.14</param>
                <param name="max">3.14</param>
            </command_interface>
            <state_interface name="position" />
            <state_interface name="velocity" />
            <state_interface name="effort" />
        </joint>
        <joint name="upper_arm_joint">
            <command_interface name="position">
                <param name="min">-3.14</param>
                <param name="max">3.14</param>
            </command_interface>
            <state_interface name="position" />
            <state_interface name="velocity" />
            <state_interface name="effort" />
        </joint>
        <joint name="elbow_joint">
            <command_interface name="position">
                <param name="min">-3.14</param>
                <param name="max">3.14</param>
            </command_interface>
            <state_interface name="position" />
            <state_interface name="velocity" />
            <state_interface name="effort" />
        </joint>
        <joint name="forearm_joint">
            <command_interface name="position">
                <param name="min">-3.14</param>
                <param name="max">3.14</param>
            </command_interface>
            <state_interface name="position" />
            <state_interface name="velocity" />
            <state_interface name="effort" />
        </joint>
        <joint name="wrist_joint">
            <command_interface name="position">
                <param name="min">-3.14</param>
                <param name="max">3.14</param>
            </command_interface>
            <state_interface name="position" />
            <state_interface name="velocity" />
            <state_interface name="effort" />
        </joint>
        <joint name="hand_joint">
            <command_interface name="position">
                <param name="min">-3.14</param>
                <param name="max">3.14</param>
            </command_interface>
            <state_interface name="position" />
            <state_interface name="velocity" />
            <state_interface name="effort" />
        </joint>
    </ros2_control>
    <!-- We need a world link because we want the base link of the robot to be anchored to it -->
    <link name="world" />
    <!-- Create a link with a given name. -->
    <link name="base_link">
        <!-- Create a visual component using a provided mesh file -->
        <visual>
            <origin rpy="0 0 0" xyz="-0.052 -0.013 0.179" />
            <geometry>
                <mesh filename="package://rr1_description/mesh/visual/01_RR1_base.dae" scale="0.001 0.001 0.001" />
            </geometry>
        </visual>
        <!-- Create a collision component using a provided mesh file -->
        <collision>
            <origin rpy="0 0 0" xyz="-0.052 -0.013 0.179" />
            <geometry>
                <mesh filename="package://rr1_description/mesh/collision/01_RR1_base.stl" scale="0.001 0.001 0.001" />
            </geometry>
        </collision>
        <!-- Insert provided inertial block -->
        <inertial>
            <origin rpy="0 0 0" xyz="0 0 0.0375" />
            <mass value="0.2" />
            <inertia ixx="0.0003602" ixy="0.0" ixz="0.0" iyy="0.0003602" iyz="0.0" izz="0.0005329" />
        </inertial>
    </link>
    <joint name="virtual_joint" type="fixed">
        <parent link="world" />
        <child link="base_link" />
        <origin xyz="0 0 0" />
    </joint>
    <!-- Create a link with a given name. -->
    <link name="shoulder_link">
        <!-- Create a visual component using a provided mesh file -->
        <visual>
            <origin rpy="0 0 0" xyz="-0.052 -0.013 0.109" />
            <geometry>
                <mesh filename="package://rr1_description/mesh/visual/02_RR1_shoulder.dae" scale="0.001 0.001 0.001" />
            </geometry>
        </visual>
        <!-- Create a collision component using a provided mesh file -->
        <collision>
            <origin rpy="0 0 0" xyz="-0.052 -0.013 0.109" />
            <geometry>
                <mesh filename="package://rr1_description/mesh/collision/02_RR1_shoulder.stl" scale="0.001 0.001 0.001" />
            </geometry>
        </collision>
        <!-- Insert provided inertial block -->
        <inertial>
            <origin rpy="0 -0.39269908169875 0" xyz="-0.04 -0.035 0.0545" />
            <mass value="0.2" />
            <inertia ixx="0.000665" ixy="0.0" ixz="0.0" iyy="0.000665" iyz="0.0" izz="0.00025000000000000006" />
        </inertial>
    </link>
    <joint name="shoulder_joint" type="revolute">
        <parent link="base_link" />
        <child link="shoulder_link" />
        <origin xyz="0 0 0.07" />
        <axis xyz="0 0 1" />
        <limit effort="30" lower="-3.14159265359" upper="3.14159265359" velocity="10" />
        <dynamics damping="10" friction="10.0" />
    </joint>
    <!-- Create a link with a given name. -->
    <link name="upper_arm_link">
        <!-- Create a visual component using a provided mesh file -->
        <visual>
            <origin rpy="0 0 0" xyz="0 -0.013 0" />
            <geometry>
                <mesh filename="package://rr1_description/mesh/visual/03_RR1_upper_arm.dae" scale="0.001 0.001 0.001" />
            </geometry>
        </visual>
        <!-- Create a collision component using a provided mesh file -->
        <collision>
            <origin rpy="0 0 0" xyz="0 -0.013 0" />
            <geometry>
                <mesh filename="package://rr1_description/mesh/collision/03_RR1_upper_arm.stl" scale="0.001 0.001 0.001" />
            </geometry>
        </collision>
        <!-- Insert provided inertial block -->
        <inertial>
            <origin rpy="0 0 0" xyz="0 0.035 0.125" />
            <mass value="0.4" />
            <inertia ixx="0.004135833333333333" ixy="0.0" ixz="0.0" iyy="0.004135833333333333" iyz="0.0" izz="0.001445" />
        </inertial>
    </link>
    <joint name="upper_arm_joint" type="revolute">
        <parent link="shoulder_link" />
        <child link="upper_arm_link" />
        <origin xyz="-0.052 0 0.109" />
        <axis xyz="0 1 0" />
        <limit effort="30" lower="-1.570796326795" upper="1.570796326795" velocity="10" />
        <dynamics damping="10" friction="10.0" />
    </joint>
    <!-- Create a link with a given name. -->
    <link name="elbow_link">
        <!-- Create a visual component using a provided mesh file -->
        <visual>
            <origin rpy="0 0 0" xyz="0 -0.013 -0.225" />
            <geometry>
                <mesh filename="package://rr1_description/mesh/visual/04_RR1_elbow.dae" scale="0.001 0.001 0.001" />
            </geometry>
        </visual>
        <!-- Create a collision component using a provided mesh file -->
        <collision>
            <origin rpy="0 0 0" xyz="0 -0.013 -0.225" />
            <geometry>
                <mesh filename="package://rr1_description/mesh/collision/04_RR1_elbow.stl" scale="0.001 0.001 0.001" />
            </geometry>
        </collision>
        <!-- Insert provided inertial block -->
        <inertial>
            <origin rpy="0 0 0" xyz="0.032 0 0.04" />
            <mass value="0.3" />
            <inertia ixx="0.0009781249999999998" ixy="0.0" ixz="0.0" iyy="0.0016593999999999997" iyz="0.0" izz="0.0008325249999999999" />
        </inertial>
    </link>
    <joint name="elbow_joint" type="revolute">
        <parent link="upper_arm_link" />
        <child link="elbow_link" />
        <origin xyz="0 0 0.225" />
        <axis xyz="0 1 0" />
        <limit effort="30" lower="-1.570796326795" upper="1.570796326795" velocity="10" />
        <dynamics damping="10" friction="10.0" />
    </joint>
    <!-- Create a link with a given name. -->
    <link name="forearm_link">
        <!-- Create a visual component using a provided mesh file -->
        <visual>
            <origin rpy="0 0 0" xyz="0 -0.0042 -0.3257" />
            <geometry>
                <mesh filename="package://rr1_description/mesh/visual/05_RR1_forearm.dae" scale="0.001 0.001 0.001" />
            </geometry>
        </visual>
        <!-- Create a collision component using a provided mesh file -->
        <collision>
            <origin rpy="0 0 0" xyz="0 -0.0042 -0.3257" />
            <geometry>
                <mesh filename="package://rr1_description/mesh/collision/05_RR1_forearm.stl" scale="0.001 0.001 0.001" />
            </geometry>
        </collision>
        <!-- Insert provided inertial block -->
        <inertial>
            <origin rpy="0 -1.570796326795 0" xyz="-0.18 0 0" />
            <mass value="0.35" />
            <inertia ixx="0.002190416666666667" ixy="0.0" ixz="0.0" iyy="0.002190416666666667" iyz="0.0" izz="0.00043749999999999995" />
        </inertial>
    </link>
    <joint name="forearm_joint" type="revolute">
        <parent link="elbow_link" />
        <child link="forearm_link" />
        <origin xyz="0 -0.0088 0.1007" />
        <axis xyz="1 0 0" />
        <limit effort="30" lower="-1.570796326795" upper="1.570796326795" velocity="10" />
        <dynamics damping="10" friction="10.0" />
    </joint>
    <!-- Create a link with a given name. -->
    <link name="wrist_link">
        <!-- Create a visual component using a provided mesh file -->
        <visual>
            <origin rpy="0 0 0" xyz="0.284 -0.0042 -0.3257" />
            <geometry>
                <mesh filename="package://rr1_description/mesh/visual/06_RR1_wrist.dae" scale="0.001 0.001 0.001" />
            </geometry>
        </visual>
        <!-- Create a collision component using a provided mesh file -->
        <collision>
            <origin rpy="0 0 0" xyz="0.284 -0.0042 -0.3257" />
            <geometry>
                <mesh filename="package://rr1_description/mesh/collision/06_RR1_wrist.stl" scale="0.001 0.001 0.001" />
            </geometry>
        </collision>
        <!-- Insert provided inertial block -->
        <inertial>
            <origin rpy="0 0 0" xyz="0 0.062 0.038" />
            <mass value="0.15" />
            <inertia ixx="0.00017544999999999998" ixy="0.0" ixz="0.0" iyy="0.00017544999999999998" iyz="0.0" izz="4.839999999999999e-05" />
        </inertial>
    </link>
    <joint name="wrist_joint" type="revolute">
        <parent link="forearm_link" />
        <child link="wrist_link" />
        <origin xyz="-0.284 0 0" />
        <axis xyz="0 1 0" />
        <limit effort="30" lower="-0.39269908169875" upper="3.14159265359" velocity="10" />
        <dynamics damping="10" friction="10.0" />
    </joint>
    <!-- Create a link with a given name. -->
    <link name="hand_link">
        <!-- Create a visual component using a provided mesh file -->
        <visual>
            <origin rpy="0 0 0" xyz="0.284 -0.07 -0.3257" />
            <geometry>
                <mesh filename="package://rr1_description/mesh/visual/07_RR1_hand.dae" scale="0.001 0.001 0.001" />
            </geometry>
        </visual>
        <!-- Create a collision component using a provided mesh file -->
        <collision>
            <origin rpy="0 0 0" xyz="0.284 -0.07 -0.3257" />
            <geometry>
                <mesh filename="package://rr1_description/mesh/collision/07_RR1_hand.stl" scale="0.001 0.001 0.001" />
            </geometry>
        </collision>
        <!-- Insert provided inertial block -->
        <inertial>
            <origin rpy="0 0 0" xyz="0 0 -0.11" />
            <mass value="0.2" />
            <inertia ixx="0.0007369791666666668" ixy="0.0" ixz="0.0" iyy="0.0007369791666666668" iyz="0.0" izz="0.000140625" />
        </inertial>
    </link>
    <joint name="hand_joint" type="revolute">
        <parent link="wrist_link" />
        <child link="hand_link" />
        <origin xyz="0 0.0658 0" />
        <axis xyz="0 0 1" />
        <limit effort="30" lower="-1.570796326795" upper="1.570796326795" velocity="10" />
        <dynamics damping="10" friction="10.0" />
    </joint>
    <transmission name="trans_shoulder_joint">
        <type>transmission_interface/SimpleTransmission</type>
        <joint name="shoulder_joint">
            <hardwareInterface>hardware_interface/PositionJointInterface</hardwareInterface>
        </joint>
        <actuator name="shoulder_joint_motor">
            <hardwareInterface>hardware_interface/PositionJointInterface</hardwareInterface>
            <mechanicalReduction>1</mechanicalReduction>
        </actuator>
    </transmission>
    <transmission name="trans_upper_arm_joint">
        <type>transmission_interface/SimpleTransmission</type>
        <joint name="upper_arm_joint">
            <hardwareInterface>hardware_interface/PositionJointInterface</hardwareInterface>
        </joint>
        <actuator name="upper_arm_joint_motor">
            <hardwareInterface>hardware_interface/PositionJointInterface</hardwareInterface>
            <mechanicalReduction>1</mechanicalReduction>
        </actuator>
    </transmission>
    <transmission name="trans_elbow_joint">
        <type>transmission_interface/SimpleTransmission</type>
        <joint name="elbow_joint">
            <hardwareInterface>hardware_interface/PositionJointInterface</hardwareInterface>
        </joint>
        <actuator name="elbow_joint_motor">
            <hardwareInterface>hardware_interface/PositionJointInterface</hardwareInterface>
            <mechanicalReduction>1</mechanicalReduction>
        </actuator>
    </transmission>
    <transmission name="trans_forearm_joint">
        <type>transmission_interface/SimpleTransmission</type>
        <joint name="forearm_joint">
            <hardwareInterface>hardware_interface/PositionJointInterface</hardwareInterface>
        </joint>
        <actuator name="forearm_joint_motor">
            <hardwareInterface>hardware_interface/PositionJointInterface</hardwareInterface>
            <mechanicalReduction>1</mechanicalReduction>
        </actuator>
    </transmission>
    <transmission name="trans_wrist_joint">
        <type>transmission_interface/SimpleTransmission</type>
        <joint name="wrist_joint">
            <hardwareInterface>hardware_interface/PositionJointInterface</hardwareInterface>
        </joint>
        <actuator name="wrist_joint_motor">
            <hardwareInterface>hardware_interface/PositionJointInterface</hardwareInterface>
            <mechanicalReduction>1</mechanicalReduction>
        </actuator>
    </transmission>
    <transmission name="trans_hand_joint">
        <type>transmission_interface/SimpleTransmission</type>
        <joint name="hand_joint">
            <hardwareInterface>hardware_interface/PositionJointInterface</hardwareInterface>
        </joint>
        <actuator name="hand_joint_motor">
            <hardwareInterface>hardware_interface/PositionJointInterface</hardwareInterface>
            <mechanicalReduction>1</mechanicalReduction>
        </actuator>
    </transmission>
</robot>

